<mujoco model="reacher">
	<compiler angle="radian" inertiafromgeom="true"/>
	<default>
		<joint armature="1" damping="1" limited="true"/>
		<geom contype="0" friction="1 0.1 0.1" rgba="0.7 0.7 0 1"/>
	</default>
	<option gravity="0 0 -9.81" integrator="RK4" timestep="0.01"/>
	
	<worldbody>
	
    	<camera name="up"  pos="0 0 0.79" xyaxes="0.001 0 0 0 3.14 0"/>
	
		<!-- Arena -->
		<geom conaffinity="0" contype="0" name="ground" pos="0 0 0" rgba="0.9 0.9 0.9 1" size="1 1 10" type="plane"/>
		
		<geom conaffinity="0" fromto="-.315 -.315 .01 .315 -.315 .01" name="sideS" rgba="0.9 0.4 0.6 1" size=".015" type="capsule"/>
		<geom conaffinity="0" fromto=" .315 -.315 .01 .315  .315 .01" name="sideE" rgba="0.9 0.4 0.6 1" size=".015" type="capsule"/>
		<geom conaffinity="0" fromto="-.315  .315 .01 .315  .315 .01" name="sideN" rgba="0.9 0.4 0.6 1" size=".015" type="capsule"/>
		<geom conaffinity="0" fromto="-.315 -.315 .01 -.315 .315 .01" name="sideW" rgba="0.9 0.4 0.6 1" size=".015" type="capsule"/>
		
		<!-- Arm -->
		<geom conaffinity="0" contype="0" fromto="0 0 0 0 0 0.02" name="root" rgba="0.9 0.4 0.6 1" size=".011" type="cylinder"/>
		<body name="body0" pos="0 0 .01">
			<geom fromto="0 0 0 0.13 0 0" name="link0" rgba="0.0 0.4 0.6 1" size=".01" type="capsule"/>
			<joint axis="0 0 1" limited="false" name="joint0" pos="0 0 0" type="hinge"/>
			<body name="body1" pos="0.13 0 0">
				<joint axis="0 0 1" limited="true" name="joint1" pos="0 0 0" range="-3.0 3.0" type="hinge"/>
				<geom fromto="0 0 0 0.13 0 0" name="link1" rgba="0.0 0.4 0.6 1" size=".01" type="capsule"/>
				
				<body name="fingertip" pos="0.13 0 0">
					<geom contype="0" name="fingertip" pos="0 0 0" rgba="0 0.2 0.4 1" size=".01" type="sphere"/>
				</body>
				
			</body>
		</body>
		<!-- Target 
		<body name="target00" pos="0 0 0.01">
			<joint armature="0" axis="1 0 0" damping="0" limited="true" name="target00_x" pos="0 0 0" range="-.27 .27" ref="0" stiffness="0" type="slide"/>
			<joint armature="0" axis="0 1 0" damping="0" limited="true" name="target00_y" pos="0 0 0" range="-.27 .27" ref="0" stiffness="0" type="slide"/>
			<geom conaffinity="0" contype="0" name="target00" pos="0 0 0" rgba="1 0 0 1" size=".022" type="sphere"/>
		</body>
		
		<body name="target01" pos="0 0 0.01">
			<joint armature="0" axis="1 0 0" damping="0" limited="true" name="target01_x" pos="0 0 0" range="-.27 .27" ref="0" stiffness="0" type="slide"/>
			<joint armature="0" axis="0 1 0" damping="0" limited="true" name="target01_y" pos="0 0 0" range="-.27 .27" ref="0" stiffness="0" type="slide"/>
			<geom conaffinity="0" contype="0" name="target01" pos="0 0 0" rgba="0 1 0 1" size=".022" type="sphere"/>
		</body>
		
		<body name="target02" pos="0 0 0.01">
			<joint armature="0" axis="1 0 0" damping="0" limited="true" name="target02_x" pos="0 0 0" range="-.27 .27" ref="0" stiffness="0" type="slide"/>
			<joint armature="0" axis="0 1 0" damping="0" limited="true" name="target02_y" pos="0 0 0" range="-.27 .27" ref="0" stiffness="0" type="slide"/>
			<geom conaffinity="0" contype="0" name="target02" pos="0 0 0" rgba="0 0 1 1" size=".022" type="sphere"/>
		</body>

        
		<body name="target10" pos="0 0 0.01">
			<joint armature="0" axis="1 0 0" damping="0" limited="true" name="target10_x" pos="0 0 0" range="-.27 .27" ref="0" stiffness="0" type="slide"/>
			<joint armature="0" axis="0 1 0" damping="0" limited="true" name="target10_y" pos="0 0 0" range="-.27 .27" ref="0" stiffness="0" type="slide"/>
			<geom conaffinity="0" contype="0" name="target10" pos="0 0 0" rgba="1 0 0 1" size=".016 0.016 0.016" type="box"/>
		</body>
		
		<body name="target11" pos="0 0 0.01">
			<joint armature="0" axis="1 0 0" damping="0" limited="true" name="target11_x" pos="0 0 0" range="-.27 .27" ref="0" stiffness="0" type="slide"/>
			<joint armature="0" axis="0 1 0" damping="0" limited="true" name="target11_y" pos="0 0 0" range="-.27 .27" ref="0" stiffness="0" type="slide"/>
			<geom conaffinity="0" contype="0" name="target11" pos="0 0 0" rgba="0 1 0 1" size=".016 0.016 0.016" type="box"/>
		</body>
		
		<body name="target12" pos="0 0 0.01">
			<joint armature="0" axis="1 0 0" damping="0" limited="true" name="target12_x" pos="0 0 0" range="-.27 .27" ref="0" stiffness="0" type="slide"/>
			<joint armature="0" axis="0 1 0" damping="0" limited="true" name="target12_y" pos="0 0 0" range="-.27 .27" ref="0" stiffness="0" type="slide"/>
			<geom conaffinity="0" contype="0" name="target12" pos="0 0 0" rgba="0 0 1 1" size=".016 0.016 0.016" type="box"/>
		</body>
		

		<body name="target20" pos="0 0 0.01">
			<joint armature="0" axis="1 0 0" damping="0" limited="true" name="target20_x" pos="0 0 0" range="-.27 .27" ref="0" stiffness="0" type="slide"/>
			<joint armature="0" axis="0 1 0" damping="0" limited="true" name="target20_y" pos="0 0 0" range="-.27 .27" ref="0" stiffness="0" type="slide"/>
			<geom conaffinity="0" contype="0" name="target20" pos="0 0 0" rgba="1 0 0 1" size=".016 0.022 0.016" type="ellipsoid"/>
		</body>
		
		<body name="target21" pos="0 0 0.01">
			<joint armature="0" axis="1 0 0" damping="0" limited="true" name="target21_x" pos="0 0 0" range="-.27 .27" ref="0" stiffness="0" type="slide"/>
			<joint armature="0" axis="0 1 0" damping="0" limited="true" name="target21_y" pos="0 0 0" range="-.27 .27" ref="0" stiffness="0" type="slide"/>
			<geom conaffinity="0" contype="0" name="target21" pos="0 0 0" rgba="0 1 0 1" size=".016 0.022 0.016" type="ellipsoid"/>
		</body>
		
		<body name="target22" pos="0 0 0.01">
			<joint armature="0" axis="1 0 0" damping="0" limited="true" name="target22_x" pos="0 0 0" range="-.27 .27" ref="0" stiffness="0" type="slide"/>
			<joint armature="0" axis="0 1 0" damping="0" limited="true" name="target22_y" pos="0 0 0" range="-.27 .27" ref="0" stiffness="0" type="slide"/>
			<geom conaffinity="0" contype="0" name="target22" pos="0 0 0" rgba="0 0 1 1" size=".016 0.022 0.016" type="ellipsoid"/>
		</body>
		
		
		
		<body name="cover" pos="0 0 0.01">
			<geom conaffinity="0" contype="0" name="cover" pos="0 0 0" rgba="0 0.2 0.4 1" size=".027 0.027 0.027" type="sphere"/>
		</body>
		
		-->
		
		
	</worldbody>
	<actuator>
		<motor ctrllimited="true" ctrlrange="-1.0 1.0" gear="200.0" joint="joint0"/>
		<motor ctrllimited="true" ctrlrange="-1.0 1.0" gear="200.0" joint="joint1"/>
	</actuator>
</mujoco>